Workbook

Sheet Cover
B11: Full Valuation Model
B13: Table of Contents:
C15: Outputs
C16: Inputs
C17: Comparative Valuation
C18: DCF Valuation

Sheet Outputs
B8: Dashboard
B10: All figures in INR Crores unless stated | H10: 2024 | I10: =H10 + 1 -> 2025 | J10: =I10 + 1 -> 2026 | K10: =J10 + 1 -> 2027 | L10: =K10 + 1 -> 2028 | M10: =L10 + 1 -> 2029 | N10: =M10 + 1 -> 2030
B12: Model Switch:
B13: =_xlfn.CONCAT("Model Currently Running:", " ", INDEX(Inputs!$B$15:$B$17, Inputs!$F$8), " ", "Scenario") -> Model Currently Running: Base Case Scenario
B15: INCOME STATEMENT
B17: Revenue | H17: ='DCF Valuation'!H13 -> 74537 | I17: ='DCF Valuation'!I13 -> 85498 | J17: ='DCF Valuation'!J13 -> 98322.7 | K17: ='DCF Valuation'!K13 -> 112579.49 | L17: ='DCF Valuation'!L13 -> 128340.62 | M17: ='DCF Valuation'!M13 -> 145987.46 | N17: ='DCF Valuation'!N13 -> 165695.76
B19: EBITDA | H19: ='DCF Valuation'!H18 -> 19774 | I19: ='DCF Valuation'!I18 -> 23555 | J19: ='DCF Valuation'!J18 -> 34412.945 | K19: ='DCF Valuation'!K18 -> 38839.925 | L19: ='DCF Valuation'!L18 -> 43635.811 | M19: ='DCF Valuation'!M18 -> 48905.798 | N19: ='DCF Valuation'!N18 -> 54679.601
B20: EBITDA Margin | H20: =H19/H17 -> 0.26529106 | I20: =I19/I17 -> 0.27550352 | J20: =J19/J17 -> 0.35 | K20: =K19/K17 -> 0.345 | L20: =L19/L17 -> 0.34 | M20: =M19/M17 -> 0.335 | N20: =N19/N17 -> 0.33
B22: Net Income | H22: ='DCF Valuation'!H30 -> 10105 | I22: ='DCF Valuation'!I30 -> 12599 | J22: ='DCF Valuation'!J30 -> 15771.67 | K22: ='DCF Valuation'!K30 -> 18423.697 | L22: ='DCF Valuation'!L30 -> 21254.885 | M22: ='DCF Valuation'!M30 -> 24331.211 | N22: ='DCF Valuation'!N30 -> 27662.702
B23: Net Income Margin | H23: =H22/H17 -> 0.13557025 | I23: =I22/I17 -> 0.14736017 | J23: =J22/J17 -> 0.16040721 | K23: =K22/K17 -> 0.16365056 | L23: =L22/L17 -> 0.16561308 | M23: =M22/M17 -> 0.16666645 | N23: =N22/N17 -> 0.16694876
B26: CASH FLOW STATEMENT
B28: Cash From Operating Activities | J28: ='DCF Valuation'!J48 -> 24714.56 | K28: ='DCF Valuation'!K48 -> 28519.347 | L28: ='DCF Valuation'!L48 -> 32279.661 | M28: ='DCF Valuation'!M48 -> 36408.147 | N28: ='DCF Valuation'!N48 -> 40939.29
B29: Cash From Investing Activities | J29: ='DCF Valuation'!J57 -> -14812.316 | K29: ='DCF Valuation'!K57 -> -16728.552 | L29: ='DCF Valuation'!L57 -> -18804.267 | M29: ='DCF Valuation'!M57 -> -21237.406 | N29: ='DCF Valuation'!N57 -> -23930.667
B30: Cash From Financing Activities | J30: ='DCF Valuation'!J66 -> -2036.0587 | K30: ='DCF Valuation'!K66 -> -2263.1091 | L30: ='DCF Valuation'!L66 -> -2507.2852 | M30: ='DCF Valuation'!M66 -> -2754.2874 | N30: ='DCF Valuation'!N66 -> -3020.3655
B31: Change in Cash | J31: =SUM(J28:J30) -> 7866.1852 | K31: =SUM(K28:K30) -> 9527.6859 | L31: =SUM(L28:L30) -> 10968.11 | M31: =SUM(M28:M30) -> 12416.453 | N31: =SUM(N28:N30) -> 13988.257
B33: Unlevered Free Cash Flows | J33: ='DCF Valuation'!J269 -> 21860.399 | K33: ='DCF Valuation'!K269 -> 24918.091 | L33: ='DCF Valuation'!L269 -> 27717.493 | M33: ='DCF Valuation'!M269 -> 30827.871 | N33: ='DCF Valuation'!N269 -> 34220.184
B54: DCF Valuation | K54: Inputs Taken
C56: Scenario Analysis | E56: Enterprise Value | G56: Equity Value | K56: Total Shares Outstanding | N56: (millions) | O56: =Inputs!K60 -> 143.78466
C57: Best Case | E57: =Inputs!O16 -> 365397.34 | G57: =E57/$O$56 -> 2541.2819 | K57: WACC | O57: =Inputs!F103 -> 0.11768508
C58: Base Case | E58: =Inputs!O17 -> 315962.18 | G58: =E58/$O$56 -> 2197.468 | K58: Terminal Growth Rate | O58: ='DCF Valuation'!E272 -> 0.03
C59: Worst Case | E59: =Inputs!O18 -> 269645.5 | G59: =E59/$O$56 -> 1875.3426 | K59: Net Debt | O59: =-'DCF Valuation'!F286 -> 22376
K60: Current Share Price | O60: =Inputs!K62 -> 8075
B63: Sensitivity Analysis
B65: Enterprise Value | J65: Equity Value
F67: Terminal Growth | N67: Terminal Growth
D68: 0.025 | E68: 0.0275 | F68: 0.03 | G68: 0.0325 | H68: 0.035 | L68: 0.025 | M68: 0.0275 | N68: 0.03 | O68: 0.0325 | P68: 0.035
B69: WACC | C69: 0.11576491 | D69: ='DCF Valuation'!F295 -> 311946.46 | E69: ='DCF Valuation'!G295 -> 317438.89 | F69: ='DCF Valuation'!H295 -> 323254.17 | G69: ='DCF Valuation'!I295 -> 329421.38 | H69: ='DCF Valuation'!J295 -> 335973.16 | J69: WACC | K69: 0.11576491 | L69: =D69-$O$59 -> 289570.46 | M69: =E69-$O$59 -> 295062.89 | N69: =F69-$O$59 -> 300878.17 | O69: =G69-$O$59 -> 307045.38 | P69: =H69-$O$59 -> 313597.16
C70: 0.11676491 | D70: ='DCF Valuation'!F296 -> 308421.75 | E70: ='DCF Valuation'!G296 -> 313763.75 | F70: ='DCF Valuation'!H296 -> 319416.2 | G70: ='DCF Valuation'!I296 -> 325406.73 | H70: ='DCF Valuation'!J296 -> 331766.31 | K70: 0.11676491 | L70: =D70-$O$59 -> 286045.75 | M70: =E70-$O$59 -> 291387.75 | N70: =F70-$O$59 -> 297040.2 | O70: =G70-$O$59 -> 303030.73 | P70: =H70-$O$59 -> 309390.31
C71: 0.11776491 | D71: ='DCF Valuation'!F297 -> 304973.38 | E71: ='DCF Valuation'!G297 -> 310170.35 | F71: ='DCF Valuation'!H297 -> 315665.97 | G71: ='DCF Valuation'!I297 -> 321486.49 | H71: ='DCF Valuation'!J297 -> 327661.33 | K71: 0.11776491 | L71: =D71-$O$59 -> 282597.38 | M71: =E71-$O$59 -> 287794.35 | N71: =F71-$O$59 -> 293289.97 | O71: =G71-$O$59 -> 299110.49 | P71: =H71-$O$59 -> 305285.33
C72: 0.11876491 | D72: ='DCF Valuation'!F298 -> 301598.91 | E72: ='DCF Valuation'!G298 -> 306656.02 | F72: ='DCF Valuation'!H298 -> 312000.52 | G72: ='DCF Valuation'!I298 -> 317657.38 | H72: ='DCF Valuation'!J298 -> 323654.55 | K72: 0.11876491 | L72: =D72-$O$59 -> 279222.91 | M72: =E72-$O$59 -> 284280.02 | N72: =F72-$O$59 -> 289624.52 | O72: =G72-$O$59 -> 295281.38 | P72: =H72-$O$59 -> 301278.55
C73: 0.11976491 | D73: ='DCF Valuation'!F299 -> 298296 | E73: ='DCF Valuation'!G299 -> 303218.17 | F73: ='DCF Valuation'!H299 -> 308417 | G73: ='DCF Valuation'!I299 -> 313916.26 | H73: ='DCF Valuation'!J299 -> 319742.51 | K73: 0.11976491 | L73: =D73-$O$59 -> 275920 | M73: =E73-$O$59 -> 280842.17 | N73: =F73-$O$59 -> 286041 | O73: =G73-$O$59 -> 291540.26 | P73: =H73-$O$59 -> 297366.51
B77: Equity per Share | J77: Premium/(Discount)
F79: Terminal Growth | N79: Terminal Growth
D80: 0.025 | E80: 0.0275 | F80: 0.03 | G80: 0.0325 | H80: 0.035 | L80: 0.025 | M80: 0.0275 | N80: 0.03 | O80: 0.0325 | P80: 0.035
B81: WACC | C81: 0.11576491 | D81: =L69/$O$56 -> 2013.9177 | E81: =M69/$O$56 -> 2052.1166 | F81: =N69/$O$56 -> 2092.561 | G81: =O69/$O$56 -> 2135.453 | H81: =P69/$O$56 -> 2181.0197 | J81: WACC | K81: 0.11576491 | L81: =D81/($O$60-1) -> 0.24943246 | M81: =E81/($O$60-1) -> 0.25416357 | N81: =F81/($O$60-1) -> 0.25917278 | O81: =G81/($O$60-1) -> 0.26448514 | P81: =H81/($O$60-1) -> 0.27012877
C82: 0.11676491 | D82: =L70/$O$56 -> 1989.4039 | E82: =M70/$O$56 -> 2026.5566 | F82: =N70/$O$56 -> 2065.8686 | G82: =O70/$O$56 -> 2107.5317 | H82: =P70/$O$56 -> 2151.7617 | K82: 0.11676491 | L82: =D82/($O$60-1) -> 0.24639632 | M82: =E82/($O$60-1) -> 0.25099785 | N82: =F82/($O$60-1) -> 0.2558668 | O82: =G82/($O$60-1) -> 0.26102697 | P82: =H82/($O$60-1) -> 0.26650504
C83: 0.11776491 | D83: =L71/$O$56 -> 1965.421 | E83: =M71/$O$56 -> 2001.5651 | F83: =N71/$O$56 -> 2039.7863 | G83: =O71/$O$56 -> 2080.2671 | H83: =P71/$O$56 -> 2123.2121 | K83: 0.11776491 | L83: =D83/($O$60-1) -> 0.24342594 | M83: =E83/($O$60-1) -> 0.24790254 | N83: =F83/($O$60-1) -> 0.2526364 | O83: =G83/($O$60-1) -> 0.25765012 | P83: =H83/($O$60-1) -> 0.26296905
C84: 0.11876491 | D84: =L72/$O$56 -> 1941.9521 | E84: =M72/$O$56 -> 1977.1235 | F84: =N72/$O$56 -> 2014.2936 | G84: =O72/$O$56 -> 2053.6362 | H84: =P72/$O$56 -> 2095.3456 | K84: 0.11876491 | L84: =D84/($O$60-1) -> 0.24051921 | M84: =E84/($O$60-1) -> 0.24487533 | N84: =F84/($O$60-1) -> 0.24947902 | O84: =G84/($O$60-1) -> 0.25435177 | P84: =H84/($O$60-1) -> 0.25951766
C85: 0.11976491 | D85: =L73/$O$56 -> 1918.9808 | E85: =M73/$O$56 -> 1953.2137 | F85: =N73/$O$56 -> 1989.3708 | G85: =O73/$O$56 -> 2027.6173 | H85: =P73/$O$56 -> 2068.138 | K85: 0.11976491 | L85: =D85/($O$60-1) -> 0.23767411 | M85: =E85/($O$60-1) -> 0.24191401 | N85: =F85/($O$60-1) -> 0.24639222 | O85: =G85/($O$60-1) -> 0.25112922 | P85: =H85/($O$60-1) -> 0.25614788
B88: Valuation Summary
...

Sheet Inputs
B8: Assumptions and Drivers | F8: 2
B10: All Figures in INR millions unless stated | H10: 2026 | I10: =H10+1 -> 2027 | J10: =I10+1 -> 2028 | K10: =J10+1 -> 2029 | L10: =K10+1 -> 2030
B11: =_xlfn.CONCAT("Model Currently Running:", " ", INDEX(Inputs!$B$15:$B$17, Inputs!$F$8), " ", "Scenario") -> Model Currently Running: Base Case Scenario
B13: Revenue Growth | H13: {=INDEX(H15:H17, $F$8)} -> 0.15 | I13: {=INDEX(I15:I17, $F$8)} -> 0.145 | J13: {=INDEX(J15:J17, $F$8)} -> 0.14 | K13: {=INDEX(K15:K17, $F$8)} -> 0.1375 | L13: {=INDEX(L15:L17, $F$8)} -> 0.135 | O13: Enterprise
O14: Value
B15: Best Case | H15: =H16 + 0.01 -> 0.16 | I15: =I16 + 0.01 -> 0.155 | J15: =J16 + 0.01 -> 0.15 | K15: =K16 + 0.01 -> 0.1475 | L15: =L16 + 0.01 -> 0.145 | O15: ='DCF Valuation'!F285 -> 315962.18
B16: Base Case | H16: 0.15 | I16: =H16-0.005 -> 0.145 | J16: =I16-0.005 -> 0.14 | K16: =J16-0.0025 -> 0.1375 | L16: =K16-0.0025 -> 0.135 | N16: 1 | O16: 365397.34
B17: Worst Case | H17: =H16-0.01 -> 0.14 | I17: =I16-0.01 -> 0.135 | J17: =J16-0.01 -> 0.13 | K17: =K16-0.01 -> 0.1275 | L17: =L16-0.01 -> 0.125 | N17: 2 | O17: 315962.18
N18: 3 | O18: 269645.5
B20: COGS | F20: (as % of revenue) | H20: {=INDEX(H22:H24, $F$8)} -> 0.25 | I20: {=INDEX(I22:I24, $F$8)} -> 0.2525 | J20: {=INDEX(J22:J24, $F$8)} -> 0.255 | K20: {=INDEX(K22:K24, $F$8)} -> 0.2575 | L20: {=INDEX(L22:L24, $F$8)} -> 0.26
B22: Best Case | H22: =H23-0.01 -> 0.24 | I22: =I23-0.01 -> 0.2425 | J22: =J23-0.01 -> 0.245 | K22: =K23-0.01 -> 0.2475 | L22: =L23-0.01 -> 0.25
B23: Base Case | H23: 0.25 | I23: =H23 +0.0025 -> 0.2525 | J23: =I23 +0.0025 -> 0.255 | K23: =J23 +0.0025 -> 0.2575 | L23: =K23 +0.0025 -> 0.26
B24: Worst Case | H24: =H23+0.01 -> 0.26 | I24: =I23+0.01 -> 0.2625 | J24: =J23+0.01 -> 0.265 | K24: =K23+0.01 -> 0.2675 | L24: =L23+0.01 -> 0.27
B27: SG&A | F27: (as % of revenue) | H27: {=INDEX(H29:H31, $F$8)} -> 0.4 | I27: {=INDEX(I29:I31, $F$8)} -> 0.4025 | J27: {=INDEX(J29:J31, $F$8)} -> 0.405 | K27: {=INDEX(K29:K31, $F$8)} -> 0.4075 | L27: {=INDEX(L29:L31, $F$8)} -> 0.41
B29: Best Case | H29: =H30-0.01 -> 0.39 | I29: =I30-0.01 -> 0.3925 | J29: =J30-0.01 -> 0.395 | K29: =K30-0.01 -> 0.3975 | L29: =L30-0.01 -> 0.4
B30: Base Case | H30: 0.4 | I30: =H30+0.0025 -> 0.4025 | J30: =I30+0.0025 -> 0.405 | K30: =J30+0.0025 -> 0.4075 | L30: =K30+0.0025 -> 0.41
B31: Worst Case | H31: =H30+0.01 -> 0.41 | I31: =I30+0.01 -> 0.4125 | J31: =J30+0.01 -> 0.415 | K31: =K30+0.01 -> 0.4175 | L31: =L30+0.01 -> 0.42
B34: Capital Expenditure | F34: (as % of revenue) | H34: {=INDEX(H36:H38, $F$8)} -> 0.08 | I34: {=INDEX(I36:I38, $F$8)} -> 0.08 | J34: {=INDEX(J36:J38, $F$8)} -> 0.08 | K34: {=INDEX(K36:K38, $F$8)} -> 0.08 | L34: {=INDEX(L36:L38, $F$8)} -> 0.08
B36: Best Case | H36: =H37-0.01 -> 0.07 | I36: =I37-0.01 -> 0.07 | J36: =J37-0.01 -> 0.07 | K36: =K37-0.01 -> 0.07 | L36: =L37-0.01 -> 0.07
B37: Base Case | H37: 0.08 | I37: =H37 -> 0.08 | J37: =I37 -> 0.08 | K37: =J37 -> 0.08 | L37: =K37 -> 0.08
B38: Worst Case | H38: =H37+0.01 -> 0.09 | I38: =I37+0.01 -> 0.09 | J38: =J37+0.01 -> 0.09 | K38: =K37+0.01 -> 0.09 | L38: =L37+0.01 -> 0.09
B41: Amounts Per Day
B43: Accounts Recievable | H43: 35 | I43: 35 | J43: 35 | K43: 35 | L43: 35
B44: Inventory | H44: 20 | I44: =H44 -> 20 | J44: =I44 -> 20 | K44: =J44 -> 20 | L44: =K44 -> 20
B45: Accounts Payable | H45: =135 -> 135 | I45: =H45 -> 135 | J45: =I45 -> 135 | K45: =J45 -> 135 | L45: =K45 -> 135
B48: Other Inputs
B50: All Figures in INR millions unless stated | H50: 2026 | I50: =H50+1 -> 2027 | J50: =I50+1 -> 2028 | K50: =J50+1 -> 2029 | L50: =K50+1 -> 2030
B52: Other Annual Inputs
B54: Inflation Rate | H54: 0.034 | I54: =H54 -> 0.034 | J54: =I54-0.001 -> 0.033 | K54: =J54-0.001 -> 0.032 | L54: =K54-0.001 -> 0.031
B55: Term Debt | E55: Increase / (Decrease) | H55: -1000 | I55: -1000 | J55: -1000 | K55: -1000 | L55: -1000
B56: Common Equity | E56: Increase / (Decrease) | H56: 0 | I56: 0 | J56: 0 | K56: 0 | L56: 0
B57: Dividend Payout Ratio | H57: 0.125 | I57: 0.125 | J57: 0.125 | K57: 0.125 | L57: 0.125
B60: Tax Rate | D60: 0.28 | H60: Shares Outstanding | K60: 143.78466
B61: Interest Rate | D61: 0.1 | H61: Terminal Growth Rate | K61: 0.03
H62: Current Share Price | K62: 8075
B64: Weighted Average Cost of Capital (WACC)
H66: Average | I66: Debt/ | J66: Debt/ | K66: Levered | L66: Unlevered
B67: Name | D67: Region | F67: Debt | G67: Equity | H67: Tax Rate | I67: Equity | J67: Capital | K67: Beta | L67: Beta
B69: Max Healthcare | D69: India | F69: 3275.02 | G69: 103012.98 | H69: 0.1382 | I69: =F69/G69 -> 0.031792304 | J69: =F69/(F69+G69) -> 0.030812698 | K69: 0.13 | L69: =K69/(1+(1-H69)*I69) -> 0.12653317
B70: Fortis Heathcare | D70: India | F70: 3194 | G70: 72627 | H70: 0.2951 | I70: =F70/G70 -> 0.043978135 | J70: =F70/(F70+G70) -> 0.042125533 | K70: 0.7 | L70: =K70/(1+(1-H70)*I70) -> 0.67895235
...

Sheet Comps Table
B8: Comprative Trading Analysis
B10: All figures in INR Millions unless stated
F12: Share | G12: Enterprise | I12: EV/ | J12: EBITDA
B13: Peer Companies | F13: Price | G13: Value | H13: EBITDA | I13: EBITDA | J13: Growth | K13: EPS | L13: P/E
F14: (inr/share) | J14: (3 Years)
B15: Apollo Hospitals | F15: =Inputs!K62 -> 8075 | G15: ='DCF Valuation'!F285 -> 315962.18 | H15: ='DCF Valuation'!I18 -> 23555 | I15: =G15/H15 -> 13.413805 | J15: 0.235 | K15: 135.04 | L15: =F15/K15 -> 59.797097
B16: Max Healthcare | F16: 1100 | G16: 1091973.3 | H16: 20040.4 | I16: =G16/H16 -> 54.488598 | J16: 0.2315 | K16: 14.6 | L16: =F16/K16 -> 75.342466
B17: Fortis Heathcare | F17: 979 | G17: 763732 | H17: 16626.7 | I17: =G17/H17 -> 45.93407 | J17: 0.1418 | K17: 12.71 | L17: =F17/K17 -> 77.025964
B18: Aster DM Health | F18: 762 | G18: 403207.2 | H18: 9896.3 | I18: =G18/H18 -> 40.743227 | J18: 0.27 | K18: 7.49 | L18: =F18/K18 -> 101.73565
B19: Narayana Hrudaya | F19: 1916 | G19: 408572.1 | H19: 13747.5 | I19: =G19/H19 -> 29.719738 | J19: 0.2534 | K19: 38.12 | L19: =F19/K19 -> 50.262329
B20: Global Health | F20: 1238 | G20: 332280.3 | H20: 10176.9 | I20: =G20/H20 -> 32.650444 | J20: 0.1404 | K20: 20.7 | L20: =F20/K20 -> 59.806763
B23: Target Company Valuation
B25: All figures in INR Millions unless stated
G27: Enterprise | I27: EV/ | J27: EBITDA
B28: Target Company Valuation | G28: Value | H28: EBITDA | I28: EBITDA | J28: Growth
J29: (3 Years)
B30: Average | G30: =H30*I30 -> 851709.08 | H30: =H15 -> 23555 | I30: =AVERAGE(I15:I20) -> 36.158314 | J30: =J15 -> 0.235
B31: Median | G31: =H31*I31 -> 864393.96 | H31: =H30 -> 23555 | I31: =MEDIAN(I15:I20) -> 36.696835 | J31: =J30 -> 0.235
B32: Maximum | G32: =H32*I32 -> 1283478.9 | H32: =H31 -> 23555 | I32: =MAX(I15:I20) -> 54.488598 | J32: =J31 -> 0.235
B33: Minimum | G33: =H33*I33 -> 315962.18 | H33: =H32 -> 23555 | I33: =MIN(I15:I20) -> 13.413805 | J33: =J32 -> 0.235

Sheet DCF Valuation
B8: Income Statement
B10: All figures in INR millions unless stated | H10: 2024 | I10: =H10 + 1 -> 2025 | J10: =I10 + 1 -> 2026 | K10: =J10 + 1 -> 2027 | L10: =K10 + 1 -> 2028 | M10: =L10 + 1 -> 2029 | N10: =M10 + 1 -> 2030
B11: =_xlfn.CONCAT("Model Currently Running:", " ", INDEX(Inputs!$B$15:$B$17, Inputs!$F$8), " ", "Scenario") -> Model Currently Running: Base Case Scenario
B13: Revenue | H13: 74537 | I13: 85498 | J13: =I13*(1+Inputs!H13) -> 98322.7 | K13: =J13*(1+Inputs!I13) -> 112579.49 | L13: =K13*(1+Inputs!J13) -> 128340.62 | M13: =L13*(1+Inputs!K13) -> 145987.46 | N13: =M13*(1+Inputs!L13) -> 165695.76
B14: COGS | H14: -19990 | I14: -22848 | J14: =-J13 * Inputs!H20 -> -24580.675 | K14: =-K13 * Inputs!I20 -> -28426.322 | L14: =-L13 * Inputs!J20 -> -32726.858 | M14: =-M13 * Inputs!K20 -> -37591.77 | N14: =-N13 * Inputs!L20 -> -43080.898
B15: Gross Profit | H15: =SUM(H13:H14) -> 54547 | I15: =SUM(I13:I14) -> 62650 | J15: =SUM(J13:J14) -> 73742.025 | K15: =SUM(K13:K14) -> 84153.17 | L15: =SUM(L13:L14) -> 95613.762 | M15: =SUM(M13:M14) -> 108395.69 | N15: =SUM(N13:N14) -> 122614.86
B17: SG&A | H17: =-(14252+20521) -> -34773 | I17: =-(15968+23127) -> -39095 | J17: =-J13 * Inputs!H27 -> -39329.08 | K17: =-K13 * Inputs!I27 -> -45313.245 | L17: =-L13 * Inputs!J27 -> -51977.951 | M17: =-M13 * Inputs!K27 -> -59489.888 | N17: =-N13 * Inputs!L27 -> -67935.262
B18: EBITDA | H18: =SUM(H15, H17) -> 19774 | I18: =SUM(I15, I17) -> 23555 | J18: =SUM(J15, J17) -> 34412.945 | K18: =SUM(K15, K17) -> 38839.925 | L18: =SUM(L15, L17) -> 43635.811 | M18: =SUM(M15, M17) -> 48905.798 | N18: =SUM(N15, N17) -> 54679.601
B20: Depreciation and Amortization | H20: -3990 | I20: -4494 | J20: =-J195 -> -9726.1479 | K20: =-K195 -> -10569.757 | L20: =-L195 -> -11533.437 | M20: =-M195 -> -12630.749 | N20: =-N195 -> -13877.482
B21: EBIT | H21: =SUM(H18, H20) -> 15784 | I21: =SUM(I18, I20) -> 19061 | J21: =SUM(J18, J20) -> 24686.797 | K21: =SUM(K18, K20) -> 28270.168 | L21: =SUM(L18, L20) -> 32102.374 | M21: =SUM(M18, M20) -> 36275.048 | N21: =SUM(N18, N20) -> 40802.119
B23: Exceptional Items | H23: 0 | I23: 0 | J23: =I23 -> 0 | K23: =J23 -> 0 | L23: =K23 -> 0 | M23: =L23 -> 0 | N23: =M23 -> 0
B24: Interest Income | H24: 0 | I24: 0 | J24: =I24 -> 0 | K24: =J24 -> 0 | L24: =K24 -> 0 | M24: =L24 -> 0 | N24: =M24 -> 0
B25: Interest Expense | H25: -2498 | I25: =-2540 -> -2540 | J25: =-J216 -> -2781.7 | K25: =-K216 -> -2681.7 | L25: =-L216 -> -2581.7 | M25: =-M216 -> -2481.7 | N25: =-N216 -> -2381.7
B26: EBT | H26: =SUM(H21, H23:H25) -> 13286 | I26: =SUM(I21, I23:I25) -> 16521 | J26: =SUM(J21, J23:J25) -> 21905.097 | K26: =SUM(K21, K23:K25) -> 25588.468 | L26: =SUM(L21, L23:L25) -> 29520.674 | M26: =SUM(M21, M23:M25) -> 33793.348 | N26: =SUM(N21, N23:N25) -> 38420.419
B28: Provision for Taxes | H28: =-3181 -> -3181 | I28: =-3922 -> -3922 | J28: =-J26 * Inputs!$D$60 -> -6133.4272 | K28: =-K26 * Inputs!$D$60 -> -7164.771 | L28: =-L26 * Inputs!$D$60 -> -8265.7886 | M28: =-M26 * Inputs!$D$60 -> -9462.1375 | N28: =-N26 * Inputs!$D$60 -> -10757.717
B30: Net Income | H30: =SUM(H26, H28) -> 10105 | I30: =SUM(I26, I28) -> 12599 | J30: =SUM(J26, J28) -> 15771.67 | K30: =SUM(K26, K28) -> 18423.697 | L30: =SUM(L26, L28) -> 21254.885 | M30: =SUM(M26, M28) -> 24331.211 | N30: =SUM(N26, N28) -> 27662.702
B33: Cash Flow Statement
B35: All Figures in INR millions unless stated | I35: 2025 | J35: =I35 + 1 -> 2026 | K35: =J35 + 1 -> 2027 | L35: =K35 + 1 -> 2028 | M35: =L35 + 1 -> 2029 | N35: =M35 + 1 -> 2030
B36: =_xlfn.CONCAT("Model Currently Running:", " ", INDEX(Inputs!$B$15:$B$17, Inputs!$F$8), " ", "Scenario") -> Model Currently Running: Base Case Scenario
B38: CASH FROM OPERATIONS
B40: Net Income | J40: =J30 -> 15771.67 | K40: =K30 -> 18423.697 | L40: =L30 -> 21254.885 | M40: =M30 -> 24331.211 | N40: =N30 -> 27662.702
B41: Depreciation & Amortization | J41: =-J20 -> 9726.1479 | K41: =-K20 -> 10569.757 | L41: =-L20 -> 11533.437 | M41: =-M20 -> 12630.749 | N41: =-N20 -> 13877.482
B42: Change in Accounts Recievable | J42: =-(J84-I84) -> -1280.2041 | K42: =-(K84-J84) -> -1367.0896 | L42: =-(L84-K84) -> -1511.3411 | M42: =-(M84-L84) -> -1692.1623 | N42: =-(N84-M84) -> -1889.8376
B43: Change in Inventory | J43: =-(J85-I85) -> -80.886301 | K43: =-(K85-J85) -> -210.72036 | L43: =-(L85-K85) -> -235.64584 | M43: =-(M85-L85) -> -266.5705 | N43: =-(N85-M85) -> -300.77416
B44: Change in Other Current Assets | J44: =-(J86-I86) -> -826.8 | K44: =-(K86-J86) -> -919.126 | L44: =-(L86-K86) -> -1016.1096 | M44: =-(M86-L86) -> -1137.6799 | N44: =-(N86-M86) -> -1270.5816
B45: Change in Accounts Payable | J45: =J101-I101 -> 864.48253 | K45: =K101-J101 -> 1422.3624 | L45: =L101-K101 -> 1590.6094 | M45: =M101-L101 -> 1799.3509 | N45: =N101-M101 -> 2030.2255
B46: Change in Other Payables | J46: 0 | K46: 0 | L46: 0 | M46: 0 | N46: 0
B47: Change in Other Current Liabilities | J47: =J103-I103 -> 540.15 | K47: =K103-J103 -> 600.46675 | L47: =L103-K103 -> 663.82634 | M47: =M103-L103 -> 743.24843 | N47: =N103-M103 -> 830.07336
B48: Cash from Operating Activities | J48: =SUM(J40:J47) -> 24714.56 | K48: =SUM(K40:K47) -> 28519.347 | L48: =SUM(L40:L47) -> 32279.661 | M48: =SUM(M40:M47) -> 36408.147 | N48: =SUM(N40:N47) -> 40939.29
B50: CASH FROM INVESTING
B52: Capital Expenditure | J52: =-J158 -> -7865.816 | K52: =-K158 -> -9006.3593 | L52: =-L158 -> -10267.25 | M52: =-M158 -> -11678.996 | N52: =-N158 -> -13255.661
B53: Change in Intangible Assets | J53: =-(J91-I91) -> 0 | K53: =-(K91-J91) -> 0 | L53: =-(L91-K91) -> 0 | M53: =-(M91-L91) -> 0 | N53: =-(N91-M91) -> 0
B54: Change in Short Term Investments | J54: =-(J83-I83) -> -2147.55 | K54: =-(K83-J83) -> -2387.3597 | L54: =-(L83-K83) -> -2639.2674 | M54: =-(M83-L83) -> -2955.0369 | N54: =-(N83-M83) -> -3300.2389
B55: Change in Investments in Long Term Assets | J55: =-(J92-I92) -> -3718.5 | K55: =-(K92-J92) -> -4133.7325 | L55: =-(L92-K92) -> -4569.9125 | M55: =-(M92-L92) -> -5116.6699 | N55: =-(N92-M92) -> -5714.39
B56: Change in Other Non-Current Assets | J56: =-(J93-I93) -> -1080.45 | K56: =-(K93-J93) -> -1201.1002 | L56: =-(L93-K93) -> -1327.837 | M56: =-(M93-L93) -> -1486.7033 | N56: =-(N93-M93) -> -1660.3772
B57: Cash from Investing Activities | J57: =SUM(J52:J56) -> -14812.316 | K57: =SUM(K52:K56) -> -16728.552 | L57: =SUM(L52:L56) -> -18804.267 | M57: =SUM(M52:M56) -> -21237.406 | N57: =SUM(N52:N56) -> -23930.667
B59: CASH FROM FINANCING
B61: Change in Current Debt | J61: =J102-I102 -> 386.85 | K61: =K102-J102 -> 430.04825 | L61: =L102-K102 -> 475.42575 | M61: =M102-L102 -> 532.30705 | N61: =N102-M102 -> 594.49019
B62: Change in Long-Term Debt | J62: =J107-I107 -> -1000 | K62: =K107-J107 -> -1000 | L62: =L107-K107 -> -1000 | M62: =M107-L107 -> -1000 | N62: =N107-M107 -> -1000
B63: Change in Other Non-Current Liabilities | J63: =J108-I108 -> 548.55 | K63: =K108-J108 -> 609.80475 | L63: =L108-K108 -> 674.14966 | M63: =M108-L108 -> 754.80686 | N63: =N108-M108 -> 842.98202
...
